<mujoco model="URDF_SO_5DOF_ARM100_05d.SLDASM">

  <compiler angle="radian" autolimits="true" balanceinertia="true"/>
  <option cone="elliptic" impratio="10" timestep="0.001"/>

  <asset>
    <mesh name="Base" file="Base.STL"/>
    <mesh name="Shoulder_Rotation_Pitch" file="Shoulder_Rotation_Pitch.STL"/>
    <mesh name="Upper_Arm" file="Upper_Arm.STL"/>
    <mesh name="Lower_Arm" file="Lower_Arm.STL"/>
    <mesh name="Wrist_Pitch_Roll" file="Wrist_Pitch_Roll.STL"/>
    <mesh name="Fixed_Gripper" file="Fixed_Gripper.STL"/>
    <mesh name="Moving_Jaw" file="Moving_Jaw.STL"/>
  </asset>


    <default>
        <joint frictionloss="0.1"/>
        <default class="low_cost_robot_6dof">
            <general biastype="affine"/>
            <joint axis="0 1 0"/>
            <default class="Shoulder_Rotation">
                <joint pos="0 0 0" axis="0 1 0" range="-60.14158 60.14158" damping="0.1"/>
                <position ctrlrange="-60.14158 60.14158" kp="25"/>
            </default>
            <default class="Shoulder_Pitch">
                <joint pos="0 0 0" axis="0 0 1" range="-2.17 1.1" damping="0.1"/>
                <position ctrlrange="-2.17 1.1" kp="25"/>
            </default>
            <default class="Elbow">
                <joint pos="0 0 0" axis="0 0 1" range="-1.5 2.25" damping="0.1"/>            
                <position ctrlrange="-1.5 2.25" kp="25"/>
            </default>
            <default class="Wrist_Pitch">
                <joint pos="0 0 0" axis="1 0 0" range="-1.95 0.725" damping="0.1"/>
                <position ctrlrange="-1.95 0.725" kp="25"/>
            </default>
            <default class="Wrist_Roll">
                <joint pos="0 0 0" axis="0 0 1" range="-1.5 1.5" damping="0.1"/>            
                <position ctrlrange="-1.5 1.5" kp="25"/>
            </default>
            <default class="Gripper">
                <joint pos="0 0 0" axis="0 0 1" range="0.032 1.5" damping="0.1"/>            
                <position ctrlrange="0.032 1.5" kp="25"/>
            </default>
        </default>
    </default>


  <worldbody>
    <geom type="mesh" rgba="0.792157 0.819608 0.933333 1" mesh="Base"/>

    <body name="Shoulder_Rotation_Pitch" pos="0 -0.0452 0.0181" quat="0.499998 0.5 0.500002 0.5">
      <inertial pos="-0.00511938 0.0678779 -0.000127472" quat="0.701891 0.690708 -0.110258 -0.134592" mass="0.11178" diaginertia="7.60171e-05 7.08845e-05 2.75921e-05"/>
      <joint name="Shoulder_Rotation" class="Shoulder_Rotation"/>
      <geom type="mesh" rgba="0.792157 0.819608 0.933333 1" mesh="Shoulder_Rotation_Pitch"/>
      
      <body name="Upper_Arm" pos="0.000125 0.1086 0" quat="-2.59734e-06 0.707105 -0.707108 2.59735e-06">      
        <inertial pos="-0.0693114 0.00293741 -7.61279e-07" quat="0.495621 0.497602 0.506001 0.500715" mass="0.167601" diaginertia="0.00023378 0.000180458 7.74993e-05"/>
        <joint name="Shoulder_Pitch" class="Shoulder_Pitch"/>
        <geom type="mesh" rgba="0.792157 0.819608 0.933333 1" mesh="Upper_Arm"/>
      
        <body name="Lower_Arm" pos="-0.11238 0.0282 0" quat="0.436087 0 0 -0.899904">
          <inertial pos="-0.058829 0.00214953 0.000146773" quat="0.500678 0.521368 0.499877 0.477095" mass="0.142523" diaginertia="0.000146983 0.000102219 6.26623e-05"/>
          <joint name="Elbow" class="Elbow"/>
          <geom type="mesh" rgba="0.792157 0.819608 0.933333 1" mesh="Lower_Arm"/>
          
          <body name="Wrist_Pitch_Roll" pos="-0.1102 0.005375 0" quat="0.63632 0.308375 0.636322 -0.308376">
            <inertial pos="-6.28656e-09 -0.00878494 -0.0309178" quat="0.601141 0.37233 0.601141 0.37233" mass="0.106402" diaginertia="7.28443e-05 5.90604e-05 4.78947e-05"/>
            <joint name="Wrist_Pitch" class="Wrist_Pitch"/>
            <geom type="mesh" rgba="0.792157 0.819608 0.933333 1" mesh="Wrist_Pitch_Roll"/>
            
            <body name="Fixed_Gripper" pos="0 0.002 -0.0545" quat="1.34924e-11 -3.67321e-06 1 -3.67321e-06">
              <inertial pos="-0.0077218 -0.000555296 0.0316942" quat="0.968374 -0.0455714 -0.211322 0.124568" mass="0.117107" diaginertia="6.09223e-05 5.76464e-05 3.8268e-05"/>
              <joint name="Wrist_Roll" class="Wrist_Roll"/>
              <geom type="mesh" rgba="0.792157 0.819608 0.933333 1" mesh="Fixed_Gripper"/>
              
              <body name="Moving_Jaw" pos="0.0202 0 0.024375" quat="0.707105 -0.707108 0 0">
                <inertial pos="-0.0033839 -0.0322884 0.000144459" quat="0.677434 0.734389 -0.0310011 -0.0282098" mass="0.0347149" diaginertia="1.37423e-05 8.29829e-06 6.98503e-06"/>
                <joint name="Gripper" class="Gripper"/>
                <geom type="mesh" rgba="0.792157 0.819608 0.933333 1" mesh="Moving_Jaw"/>
              
              </body>
            </body>
          </body>
        </body>
      </body>
    </body>
  </worldbody>

<actuator>
    <position class="Shoulder_Rotation" name="Shoulder_Rotation_actuator" joint="Shoulder_Rotation"/>
    <position class="Shoulder_Pitch"  name="Shoulder_Pitch_actuator" joint="Shoulder_Pitch"/>
    <position class="Elbow"  name="Elbow_actuator" joint="Elbow"/>
    <position class="Wrist_Pitch"  name="Wrist_Pitch_actuator" joint="Wrist_Pitch"/>
    <position class="Wrist_Roll"  name="Wrist_Roll_actuator" joint="Wrist_Roll"/>
    <position class="Gripper"  name="Gripper_actuator" joint="Gripper"/>
</actuator>

</mujoco>
