<robot name="onshape">
<link name="simple_base_v9">
<visual>
<origin xyz="0.040155457064714572546 -0.035375356536268762198 -0.024242697970273636293" rpy="0 -0 0" />
<geometry>
<mesh filename="package:///base.stl"/>
</geometry>
<material name="base_material">
<color rgba="0.64705882352941179736 0.64705882352941179736 0.64705882352941179736 1.0"/>
</material>
</visual>
<collision>
<origin xyz="0.040155457064714572546 -0.035375356536268762198 -0.024242697970273636293" rpy="0 -0 0" />
<geometry>
<mesh filename="package:///base.stl"/>
</geometry>
</collision>
<visual>
<origin xyz="0.051155457064714568438 0.040624643463731187343 0.0099573020297263406531" rpy="-5.0359163561673113486e-46 -0 3.141592653589793116" />
<geometry>
<mesh filename="package:///dc11_a01_spacer_dummy.stl"/>
</geometry>
<material name="dc11_a01_spacer_dummy_material">
<color rgba="0.64705882352941179736 0.64705882352941179736 0.64705882352941179736 1.0"/>
</material>
</visual>
<collision>
<origin xyz="0.051155457064714568438 0.040624643463731187343 0.0099573020297263406531" rpy="-5.0359163561673113486e-46 -0 3.141592653589793116" />
<geometry>
<mesh filename="package:///dc11_a01_spacer_dummy.stl"/>
</geometry>
</collision>
<visual>
<origin xyz="0.029155457064714576654 0.00062464346373123508238 0.0099573020297263406531" rpy="-5.0359163561673113486e-46 -0 3.141592653589793116" />
<geometry>
<mesh filename="package:///dc11_a01_spacer_dummy.stl"/>
</geometry>
<material name="dc11_a01_spacer_dummy_material">
<color rgba="0.64705882352941179736 0.64705882352941179736 0.64705882352941179736 1.0"/>
</material>
</visual>
<collision>
<origin xyz="0.029155457064714576654 0.00062464346373123508238 0.0099573020297263406531" rpy="-5.0359163561673113486e-46 -0 3.141592653589793116" />
<geometry>
<mesh filename="package:///dc11_a01_spacer_dummy.stl"/>
</geometry>
</collision>
<visual>
<origin xyz="0.051155457064714568438 0.00062464346373122814349 -0.018442697970273640162" rpy="3.141592653589793116 -0 3.141592653589793116" />
<geometry>
<mesh filename="package:///dc11_a01_spacer_dummy.stl"/>
</geometry>
<material name="dc11_a01_spacer_dummy_material">
<color rgba="0.64705882352941179736 0.64705882352941179736 0.64705882352941179736 1.0"/>
</material>
</visual>
<collision>
<origin xyz="0.051155457064714568438 0.00062464346373122814349 -0.018442697970273640162" rpy="3.141592653589793116 -0 3.141592653589793116" />
<geometry>
<mesh filename="package:///dc11_a01_spacer_dummy.stl"/>
</geometry>
</collision>
<visual>
<origin xyz="0.040155457064714558668 0.032624643463731207993 -0.0042426979702736497546" rpy="5.0359163561673113486e-46 -0 0" />
<geometry>
<mesh filename="package:///dc11_a01_dummy.stl"/>
</geometry>
<material name="dc11_a01_dummy_material">
<color rgba="0.49803921568627451677 0.49803921568627451677 0.49803921568627451677 1.0"/>
</material>
</visual>
<collision>
<origin xyz="0.040155457064714558668 0.032624643463731207993 -0.0042426979702736497546" rpy="5.0359163561673113486e-46 -0 0" />
<geometry>
<mesh filename="package:///dc11_a01_dummy.stl"/>
</geometry>
</collision>
<visual>
<origin xyz="0.029155457064714576654 0.00062464346373123508238 -0.018442697970273640162" rpy="3.141592653589793116 -1.0071832712334613363e-45 1.570796326794896558" />
<geometry>
<mesh filename="package:///dc11_a01_spacer_dummy.stl"/>
</geometry>
<material name="dc11_a01_spacer_dummy_material">
<color rgba="0.64705882352941179736 0.64705882352941179736 0.64705882352941179736 1.0"/>
</material>
</visual>
<collision>
<origin xyz="0.029155457064714576654 0.00062464346373123508238 -0.018442697970273640162" rpy="3.141592653589793116 -1.0071832712334613363e-45 1.570796326794896558" />
<geometry>
<mesh filename="package:///dc11_a01_spacer_dummy.stl"/>
</geometry>
</collision>
<visual>
<origin xyz="0.029155457064714569715 0.040624643463731187343 0.0099573020297263406531" rpy="8.326672684688659262e-17 1.0071832712334613363e-45 -1.570796326794896558" />
<geometry>
<mesh filename="package:///dc11_a01_spacer_dummy.stl"/>
</geometry>
<material name="dc11_a01_spacer_dummy_material">
<color rgba="0.64705882352941179736 0.64705882352941179736 0.64705882352941179736 1.0"/>
</material>
</visual>
<collision>
<origin xyz="0.029155457064714569715 0.040624643463731187343 0.0099573020297263406531" rpy="8.326672684688659262e-17 1.0071832712334613363e-45 -1.570796326794896558" />
<geometry>
<mesh filename="package:///dc11_a01_spacer_dummy.stl"/>
</geometry>
</collision>
<visual>
<origin xyz="0.051155457064714568438 0.040624643463731187343 -0.018442697970273640162" rpy="3.141592653589793116 1.0071832712334613363e-45 -1.570796326794896558" />
<geometry>
<mesh filename="package:///dc11_a01_spacer_dummy.stl"/>
</geometry>
<material name="dc11_a01_spacer_dummy_material">
<color rgba="0.64705882352941179736 0.64705882352941179736 0.64705882352941179736 1.0"/>
</material>
</visual>
<collision>
<origin xyz="0.051155457064714568438 0.040624643463731187343 -0.018442697970273640162" rpy="3.141592653589793116 1.0071832712334613363e-45 -1.570796326794896558" />
<geometry>
<mesh filename="package:///dc11_a01_spacer_dummy.stl"/>
</geometry>
</collision>
<visual>
<origin xyz="0.029155457064714569715 0.040624643463731187343 -0.018442697970273640162" rpy="-3.141592653589793116 -0 0" />
<geometry>
<mesh filename="package:///dc11_a01_spacer_dummy.stl"/>
</geometry>
<material name="dc11_a01_spacer_dummy_material">
<color rgba="0.64705882352941179736 0.64705882352941179736 0.64705882352941179736 1.0"/>
</material>
</visual>
<collision>
<origin xyz="0.029155457064714569715 0.040624643463731187343 -0.018442697970273640162" rpy="-3.141592653589793116 -0 0" />
<geometry>
<mesh filename="package:///dc11_a01_spacer_dummy.stl"/>
</geometry>
</collision>
<visual>
<origin xyz="0.051155457064714568438 0.00062464346373122814349 0.0099573020297263406531" rpy="0 -1.0071832712334613363e-45 1.570796326794896558" />
<geometry>
<mesh filename="package:///dc11_a01_spacer_dummy.stl"/>
</geometry>
<material name="dc11_a01_spacer_dummy_material">
<color rgba="0.64705882352941179736 0.64705882352941179736 0.64705882352941179736 1.0"/>
</material>
</visual>
<collision>
<origin xyz="0.051155457064714568438 0.00062464346373122814349 0.0099573020297263406531" rpy="0 -1.0071832712334613363e-45 1.570796326794896558" />
<geometry>
<mesh filename="package:///dc11_a01_spacer_dummy.stl"/>
</geometry>
</collision>
<inertial>
<origin xyz="0.039980049082059543331 0.010998727713006284032 -0.0097178975728691736197" rpy="0 0 0"/>
<mass value="0.08053960224652947919" />
<inertia ixx="4.7629046744397422958e-05" ixy="-2.3508900351551016034e-07"  ixz="-1.2043707630690469949e-07" iyy="4.4681661135621436349e-05" iyz="-9.9824602731646885348e-06" izz="6.9493691498257871932e-05" />
</inertial>
</link>

<link name="pitch1_assembly">
<visual>
<origin xyz="0 0 -0.02089999999999999844" rpy="3.1115076389305708536e-61 6.2654008338041894323e-63 4.6222318665293660473e-33" />
<geometry>
<mesh filename="package:///rotation_connector.stl"/>
</geometry>
<material name="rotation_connector_material">
<color rgba="0.2313725490196078538 0.38039215686274507888 0.7058823529411765163 1.0"/>
</material>
</visual>
<collision>
<origin xyz="0 0 -0.02089999999999999844" rpy="3.1115076389305708536e-61 6.2654008338041894323e-63 4.6222318665293660473e-33" />
<geometry>
<mesh filename="package:///rotation_connector.stl"/>
</geometry>
</collision>
<visual>
<origin xyz="-0.013999999999999981209 0.0080000000000000487388 0.026399999999999958222" rpy="-3.141592653589793116 1.570796326794896558 0" />
<geometry>
<mesh filename="package:///dc11_a01_spacer_dummy.stl"/>
</geometry>
<material name="dc11_a01_spacer_dummy_material">
<color rgba="0.64705882352941179736 0.64705882352941179736 0.64705882352941179736 1.0"/>
</material>
</visual>
<collision>
<origin xyz="-0.013999999999999981209 0.0080000000000000487388 0.026399999999999958222" rpy="-3.141592653589793116 1.570796326794896558 0" />
<geometry>
<mesh filename="package:///dc11_a01_spacer_dummy.stl"/>
</geometry>
</collision>
<visual>
<origin xyz="-0.013999999999999967332 -0.031999999999999993727 0.0044000000000000323575" rpy="-3.141592653589793116 1.570796326794896558 0" />
<geometry>
<mesh filename="package:///dc11_a01_spacer_dummy.stl"/>
</geometry>
<material name="dc11_a01_spacer_dummy_material">
<color rgba="0.64705882352941179736 0.64705882352941179736 0.64705882352941179736 1.0"/>
</material>
</visual>
<collision>
<origin xyz="-0.013999999999999967332 -0.031999999999999993727 0.0044000000000000323575" rpy="-3.141592653589793116 1.570796326794896558 0" />
<geometry>
<mesh filename="package:///dc11_a01_spacer_dummy.stl"/>
</geometry>
</collision>
<visual>
<origin xyz="0.014399999999999996136 -0.031999999999999993727 0.026399999999999965161" rpy="9.0205620750793919606e-17 1.570796326794896558 0" />
<geometry>
<mesh filename="package:///dc11_a01_spacer_dummy.stl"/>
</geometry>
<material name="dc11_a01_spacer_dummy_material">
<color rgba="0.64705882352941179736 0.64705882352941179736 0.64705882352941179736 1.0"/>
</material>
</visual>
<collision>
<origin xyz="0.014399999999999996136 -0.031999999999999993727 0.026399999999999965161" rpy="9.0205620750793919606e-17 1.570796326794896558 0" />
<geometry>
<mesh filename="package:///dc11_a01_spacer_dummy.stl"/>
</geometry>
</collision>
<visual>
<origin xyz="0.00019999999999999878986 7.6327832942979512154e-17 0.015399999999999983147" rpy="-9.0205620750793919606e-17 -1.570796326794896558 0" />
<geometry>
<mesh filename="package:///dc11_a01_dummy.stl"/>
</geometry>
<material name="dc11_a01_dummy_material">
<color rgba="0.49803921568627451677 0.49803921568627451677 0.49803921568627451677 1.0"/>
</material>
</visual>
<collision>
<origin xyz="0.00019999999999999878986 7.6327832942979512154e-17 0.015399999999999983147" rpy="-9.0205620750793919606e-17 -1.570796326794896558 0" />
<geometry>
<mesh filename="package:///dc11_a01_dummy.stl"/>
</geometry>
</collision>
<visual>
<origin xyz="0.014400000000000003075 -0.031999999999999993727 0.0044000000000000046019" rpy="1.570796326794896558 5.9164567891575964229e-31 1.570796326794896558" />
<geometry>
<mesh filename="package:///dc11_a01_spacer_dummy.stl"/>
</geometry>
<material name="dc11_a01_spacer_dummy_material">
<color rgba="0.64705882352941179736 0.64705882352941179736 0.64705882352941179736 1.0"/>
</material>
</visual>
<collision>
<origin xyz="0.014400000000000003075 -0.031999999999999993727 0.0044000000000000046019" rpy="1.570796326794896558 5.9164567891575964229e-31 1.570796326794896558" />
<geometry>
<mesh filename="package:///dc11_a01_spacer_dummy.stl"/>
</geometry>
</collision>
<visual>
<origin xyz="-0.013999999999999967332 0.0080000000000000417999 0.0044000000000000323575" rpy="1.57079632679489678 -5.9164567891575964229e-31 -1.57079632679489678" />
<geometry>
<mesh filename="package:///dc11_a01_spacer_dummy.stl"/>
</geometry>
<material name="dc11_a01_spacer_dummy_material">
<color rgba="0.64705882352941179736 0.64705882352941179736 0.64705882352941179736 1.0"/>
</material>
</visual>
<collision>
<origin xyz="-0.013999999999999967332 0.0080000000000000417999 0.0044000000000000323575" rpy="1.57079632679489678 -5.9164567891575964229e-31 -1.57079632679489678" />
<geometry>
<mesh filename="package:///dc11_a01_spacer_dummy.stl"/>
</geometry>
</collision>
<visual>
<origin xyz="0.014399999999999996136 0.0080000000000000626166 0.026399999999999965161" rpy="-1.570796326794896558 -5.9164567891575964229e-31 -1.57079632679489678" />
<geometry>
<mesh filename="package:///dc11_a01_spacer_dummy.stl"/>
</geometry>
<material name="dc11_a01_spacer_dummy_material">
<color rgba="0.64705882352941179736 0.64705882352941179736 0.64705882352941179736 1.0"/>
</material>
</visual>
<collision>
<origin xyz="0.014399999999999996136 0.0080000000000000626166 0.026399999999999965161" rpy="-1.570796326794896558 -5.9164567891575964229e-31 -1.57079632679489678" />
<geometry>
<mesh filename="package:///dc11_a01_spacer_dummy.stl"/>
</geometry>
</collision>
<visual>
<origin xyz="0.014400000000000003075 0.0080000000000000556777 0.0044000000000000046019" rpy="3.141592653589793116 -1.570796326794896558 0" />
<geometry>
<mesh filename="package:///dc11_a01_spacer_dummy.stl"/>
</geometry>
<material name="dc11_a01_spacer_dummy_material">
<color rgba="0.64705882352941179736 0.64705882352941179736 0.64705882352941179736 1.0"/>
</material>
</visual>
<collision>
<origin xyz="0.014400000000000003075 0.0080000000000000556777 0.0044000000000000046019" rpy="3.141592653589793116 -1.570796326794896558 0" />
<geometry>
<mesh filename="package:///dc11_a01_spacer_dummy.stl"/>
</geometry>
</collision>
<visual>
<origin xyz="-0.013999999999999974271 -0.031999999999999993727 0.026399999999999958222" rpy="-1.57079632679489678 5.9164567891575964229e-31 1.570796326794896558" />
<geometry>
<mesh filename="package:///dc11_a01_spacer_dummy.stl"/>
</geometry>
<material name="dc11_a01_spacer_dummy_material">
<color rgba="0.64705882352941179736 0.64705882352941179736 0.64705882352941179736 1.0"/>
</material>
</visual>
<collision>
<origin xyz="-0.013999999999999974271 -0.031999999999999993727 0.026399999999999958222" rpy="-1.57079632679489678 5.9164567891575964229e-31 1.570796326794896558" />
<geometry>
<mesh filename="package:///dc11_a01_spacer_dummy.stl"/>
</geometry>
</collision>
<inertial>
<origin xyz="-0.00076710298260102872947 -0.012150475340123870899 0.013424089991769168687" rpy="0 0 0"/>
<mass value="0.060683050410559984111" />
<inertia ixx="1.7263083351491901045e-05" ixy="3.2150766683281251029e-07"  ixz="9.234401318697589615e-08" iyy="1.1188349425195259014e-05" iyz="-1.2056959520257657199e-07" izz="1.8618518418570228741e-05" />
</inertial>
</link>

<link name="pitch2_assembly">
<visual>
<origin xyz="0 -1.3877787807814456755e-17 0.018999999999999992589" rpy="-1.570796326794896558 -1.570796326794896336 0" />
<geometry>
<mesh filename="package:///arm_connector.stl"/>
</geometry>
<material name="arm_connector_material">
<color rgba="0.98039215686274505668 0.71372549019607844922 0.0039215686274509803377 1.0"/>
</material>
</visual>
<collision>
<origin xyz="0 -1.3877787807814456755e-17 0.018999999999999992589" rpy="-1.570796326794896558 -1.570796326794896336 0" />
<geometry>
<mesh filename="package:///arm_connector.stl"/>
</geometry>
</collision>
<visual>
<origin xyz="0.10829999999999974369 -0.014799999999999896572 0.030349999999998825834" rpy="9.5998729628472362489e-16 -6.7457869493600303443e-15 1.1657341758564471052e-15" />
<geometry>
<mesh filename="package:///dc15_a01_horn_idle2_dummy.stl"/>
</geometry>
<material name="dc15_a01_horn_idle2_dummy_material">
<color rgba="0.64705882352941179736 0.64705882352941179736 0.64705882352941179736 1.0"/>
</material>
</visual>
<collision>
<origin xyz="0.10829999999999974369 -0.014799999999999896572 0.030349999999998825834" rpy="9.5998729628472362489e-16 -6.7457869493600303443e-15 1.1657341758564471052e-15" />
<geometry>
<mesh filename="package:///dc15_a01_horn_idle2_dummy.stl"/>
</geometry>
</collision>
<visual>
<origin xyz="0.10830000000000002125 -0.014799999999999952083 0.010750000000000006078" rpy="-3.141592653589793116 2.0249749451786960699e-15 5.551115123128824747e-17" />
<geometry>
<mesh filename="package:///dc15_a01_case_m_dummy.stl"/>
</geometry>
<material name="dc15_a01_case_m_dummy_material">
<color rgba="0.61568627450980395466 0.81176470588235294379 0.92941176470588238168 1.0"/>
</material>
</visual>
<collision>
<origin xyz="0.10830000000000002125 -0.014799999999999952083 0.010750000000000006078" rpy="-3.141592653589793116 2.0249749451786960699e-15 5.551115123128824747e-17" />
<geometry>
<mesh filename="package:///dc15_a01_case_m_dummy.stl"/>
</geometry>
</collision>
<visual>
<origin xyz="0.10830000000000002125 -0.014799999999999952083 0.010750000000000006078" rpy="-3.141592653589793116 2.0249749451786960699e-15 5.551115123128824747e-17" />
<geometry>
<mesh filename="package:///dc15_a01_case_f_dummy.stl"/>
</geometry>
<material name="dc15_a01_case_f_dummy_material">
<color rgba="0.98039215686274505668 0.71372549019607844922 0.0039215686274509803377 1.0"/>
</material>
</visual>
<collision>
<origin xyz="0.10830000000000002125 -0.014799999999999952083 0.010750000000000006078" rpy="-3.141592653589793116 2.0249749451786960699e-15 5.551115123128824747e-17" />
<geometry>
<mesh filename="package:///dc15_a01_case_f_dummy.stl"/>
</geometry>
</collision>
<visual>
<origin xyz="0.10830000000000002125 -0.01479999999999984106 0.0071499999999997954081" rpy="-1.5707963267948974462 1.0836495237717367213e-15 -3.1415926535897615857" />
<geometry>
<mesh filename="package:///dc15_a01_horn_dummy.stl"/>
</geometry>
<material name="dc15_a01_horn_dummy_material">
<color rgba="0.97254901960784312376 0.52941176470588235947 0.0039215686274509803377 1.0"/>
</material>
</visual>
<collision>
<origin xyz="0.10830000000000002125 -0.01479999999999984106 0.0071499999999997954081" rpy="-1.5707963267948974462 1.0836495237717367213e-15 -3.1415926535897615857" />
<geometry>
<mesh filename="package:///dc15_a01_horn_dummy.stl"/>
</geometry>
</collision>
<visual>
<origin xyz="0.10829999999999974369 -0.014799999999999896572 0.030250000000000002581" rpy="-3.141592653589793116 2.0249749451786960699e-15 5.551115123128824747e-17" />
<geometry>
<mesh filename="package:///dc15_a01_case_b_dummy.stl"/>
</geometry>
<material name="dc15_a01_case_b_dummy_material">
<color rgba="0.49803921568627451677 0.49803921568627451677 0.49803921568627451677 1.0"/>
</material>
</visual>
<collision>
<origin xyz="0.10829999999999974369 -0.014799999999999896572 0.030250000000000002581" rpy="-3.141592653589793116 2.0249749451786960699e-15 5.551115123128824747e-17" />
<geometry>
<mesh filename="package:///dc15_a01_case_b_dummy.stl"/>
</geometry>
</collision>
<inertial>
<origin xyz="0.076624233055629403788 -0.00031228998750630301189 0.018740205891557192019" rpy="0 0 0"/>
<mass value="0.043244618106601871721" />
<inertia ixx="1.1148341428851390496e-05" ixy="4.8956544773565029542e-06"  ixz="3.6379254892495212553e-07" iyy="7.1784738134705731224e-05" iyz="-9.2212677143649640549e-08" izz="7.0310516633826915201e-05" />
</inertial>
</link>

<link name="pitch3_assembly">
<visual>
<origin xyz="-0.0086303090998643833265 0.0084737572034786490249 0.01450000000000000247" rpy="1.570796326794896558 1.570796326794896558 0" />
<geometry>
<mesh filename="package:///connector.stl"/>
</geometry>
<material name="connector_material">
<color rgba="0.61568627450980395466 0.81176470588235294379 0.92941176470588238168 1.0"/>
</material>
</visual>
<collision>
<origin xyz="-0.0086303090998643833265 0.0084737572034786490249 0.01450000000000000247" rpy="1.570796326794896558 1.570796326794896558 0" />
<geometry>
<mesh filename="package:///connector.stl"/>
</geometry>
</collision>
<visual>
<origin xyz="-0.10047608430634659415 -0.0026998601445658854114 0.026349999999999800665" rpy="3.5618106130407824487e-14 -7.9856017255641821947e-15 -1.5707963267948972241" />
<geometry>
<mesh filename="package:///dc15_a01_horn_idle2_dummy.stl"/>
</geometry>
<material name="dc15_a01_horn_idle2_dummy_material">
<color rgba="0.64705882352941179736 0.64705882352941179736 0.64705882352941179736 1.0"/>
</material>
</visual>
<collision>
<origin xyz="-0.10047608430634659415 -0.0026998601445658854114 0.026349999999999800665" rpy="3.5618106130407824487e-14 -7.9856017255641821947e-15 -1.5707963267948972241" />
<geometry>
<mesh filename="package:///dc15_a01_horn_idle2_dummy.stl"/>
</geometry>
</collision>
<visual>
<origin xyz="-0.10047608430634587251 -0.0026998601445660519449 0.006750000000000967032" rpy="-3.141592653589758033 -2.1404055318796187029e-16 -1.5707963267948974462" />
<geometry>
<mesh filename="package:///dc15_a01_case_m_dummy.stl"/>
</geometry>
<material name="dc15_a01_case_m_dummy_material">
<color rgba="0.61568627450980395466 0.81176470588235294379 0.92941176470588238168 1.0"/>
</material>
</visual>
<collision>
<origin xyz="-0.10047608430634587251 -0.0026998601445660519449 0.006750000000000967032" rpy="-3.141592653589758033 -2.1404055318796187029e-16 -1.5707963267948974462" />
<geometry>
<mesh filename="package:///dc15_a01_case_m_dummy.stl"/>
</geometry>
</collision>
<visual>
<origin xyz="-0.10047608430634587251 -0.0026998601445660519449 0.006750000000000967032" rpy="-3.141592653589758033 -2.1404055318796187029e-16 -1.5707963267948974462" />
<geometry>
<mesh filename="package:///dc15_a01_case_f_dummy.stl"/>
</geometry>
<material name="dc15_a01_case_f_dummy_material">
<color rgba="0.98039215686274505668 0.71372549019607844922 0.0039215686274509803377 1.0"/>
</material>
</visual>
<collision>
<origin xyz="-0.10047608430634587251 -0.0026998601445660519449 0.006750000000000967032" rpy="-3.141592653589758033 -2.1404055318796187029e-16 -1.5707963267948974462" />
<geometry>
<mesh filename="package:///dc15_a01_case_f_dummy.stl"/>
</geometry>
</collision>
<visual>
<origin xyz="-0.10047608430634567822 -0.0026998601445660797005 0.0031500000000007424839" rpy="-1.5707963267949320851 1.1022189728881637207e-15 1.570796326794941189" />
<geometry>
<mesh filename="package:///dc15_a01_horn_dummy.stl"/>
</geometry>
<material name="dc15_a01_horn_dummy_material">
<color rgba="0.97254901960784312376 0.52941176470588235947 0.0039215686274509803377 1.0"/>
</material>
</visual>
<collision>
<origin xyz="-0.10047608430634567822 -0.0026998601445660797005 0.0031500000000007424839" rpy="-1.5707963267949320851 1.1022189728881637207e-15 1.570796326794941189" />
<geometry>
<mesh filename="package:///dc15_a01_horn_dummy.stl"/>
</geometry>
</collision>
<visual>
<origin xyz="-0.1004760843063465664 -0.0026998601445658854114 0.026250000000000963535" rpy="-3.141592653589758033 -2.1404055318796187029e-16 -1.5707963267948974462" />
<geometry>
<mesh filename="package:///dc15_a01_case_b_dummy.stl"/>
</geometry>
<material name="dc15_a01_case_b_dummy_material">
<color rgba="0.49803921568627451677 0.49803921568627451677 0.49803921568627451677 1.0"/>
</material>
</visual>
<collision>
<origin xyz="-0.1004760843063465664 -0.0026998601445658854114 0.026250000000000963535" rpy="-3.141592653589758033 -2.1404055318796187029e-16 -1.5707963267948974462" />
<geometry>
<mesh filename="package:///dc15_a01_case_b_dummy.stl"/>
</geometry>
</collision>
<inertial>
<origin xyz="-0.055101435764595849132 -0.0028779165917363859137 0.014481329584651056117" rpy="0 0 0"/>
<mass value="0.078833516652619811671" />
<inertia ixx="9.8450262832195919381e-06" ixy="-5.4577382769762468172e-08"  ixz="-1.0104764712519052589e-07" iyy="6.8091179715556247984e-05" iyz="-1.4399351967403872763e-09" izz="6.4574585130602074503e-05" />
</inertial>
</link>

<link name="effector_roll_assembly">
<visual>
<origin xyz="-0.010999801038367840178 -0.019000198961632130956 0.039000000000000013822" rpy="-1.570796326794896558 7.9083214522059648937e-32 4.4734547651796471821e-30" />
<geometry>
<mesh filename="package:///shoulder_rotation.stl"/>
</geometry>
<material name="shoulder_rotation_material">
<color rgba="0.61568627450980395466 0.81176470588235294379 0.92941176470588238168 1.0"/>
</material>
</visual>
<collision>
<origin xyz="-0.010999801038367840178 -0.019000198961632130956 0.039000000000000013822" rpy="-1.570796326794896558 7.9083214522059648937e-32 4.4734547651796471821e-30" />
<geometry>
<mesh filename="package:///shoulder_rotation.stl"/>
</geometry>
</collision>
<visual>
<origin xyz="-7.4415414746398234058e-06 -0.038500198961634146677 0.013396676675037341719" rpy="-1.570796326794896558 2.2204460492904656079e-16 -3.141592653589793116" />
<geometry>
<mesh filename="package:///dc15_a01_case_m_dummy.stl"/>
</geometry>
<material name="dc15_a01_case_m_dummy_material">
<color rgba="0.61568627450980395466 0.81176470588235294379 0.92941176470588238168 1.0"/>
</material>
</visual>
<collision>
<origin xyz="-7.4415414746398234058e-06 -0.038500198961634146677 0.013396676675037341719" rpy="-1.570796326794896558 2.2204460492904656079e-16 -3.141592653589793116" />
<geometry>
<mesh filename="package:///dc15_a01_case_m_dummy.stl"/>
</geometry>
</collision>
<visual>
<origin xyz="-7.4415414746398234058e-06 -0.038500198961634146677 0.013396676675037341719" rpy="-1.570796326794896558 2.2204460492904656079e-16 -3.141592653589793116" />
<geometry>
<mesh filename="package:///dc15_a01_case_f_dummy.stl"/>
</geometry>
<material name="dc15_a01_case_f_dummy_material">
<color rgba="0.98039215686274505668 0.71372549019607844922 0.0039215686274509803377 1.0"/>
</material>
</visual>
<collision>
<origin xyz="-7.4415414746398234058e-06 -0.038500198961634146677 0.013396676675037341719" rpy="-1.570796326794896558 2.2204460492904656079e-16 -3.141592653589793116" />
<geometry>
<mesh filename="package:///dc15_a01_case_f_dummy.stl"/>
</geometry>
</collision>
<visual>
<origin xyz="-7.441541474917379162e-06 -0.042100198961634333061 0.013396676675037334781" rpy="3.1415926535897842342 -1.4876988529978893089e-14 -7.8879269721494039036e-14" />
<geometry>
<mesh filename="package:///dc15_a01_horn_dummy.stl"/>
</geometry>
<material name="dc15_a01_horn_dummy_material">
<color rgba="0.97254901960784312376 0.52941176470588235947 0.0039215686274509803377 1.0"/>
</material>
</visual>
<collision>
<origin xyz="-7.441541474917379162e-06 -0.042100198961634333061 0.013396676675037334781" rpy="3.1415926535897842342 -1.4876988529978893089e-14 -7.8879269721494039036e-14" />
<geometry>
<mesh filename="package:///dc15_a01_horn_dummy.stl"/>
</geometry>
</collision>
<visual>
<origin xyz="-7.4415414726969331127e-06 -0.019000198961632130956 0.01339667667503708498" rpy="-1.570796326794896558 2.2204460492904656079e-16 -3.141592653589793116" />
<geometry>
<mesh filename="package:///dc15_a01_case_b_dummy.stl"/>
</geometry>
<material name="dc15_a01_case_b_dummy_material">
<color rgba="0.49803921568627451677 0.49803921568627451677 0.49803921568627451677 1.0"/>
</material>
</visual>
<collision>
<origin xyz="-7.4415414726969331127e-06 -0.019000198961632130956 0.01339667667503708498" rpy="-1.570796326794896558 2.2204460492904656079e-16 -3.141592653589793116" />
<geometry>
<mesh filename="package:///dc15_a01_case_b_dummy.stl"/>
</geometry>
</collision>
<inertial>
<origin xyz="-1.6501701644226806145e-05 -0.026590019948449127724 0.019538786400953758737" rpy="0 0 0"/>
<mass value="0.024050576744299754367" />
<inertia ixx="6.0320728599489946805e-06" ixy="-2.4433761657110800971e-09"  ixz="2.3042659758129468033e-09" iyy="3.7952439277730995642e-06" iyz="3.8450169416725924111e-07" izz="3.6859019059960994889e-06" />
</inertial>
</link>

<link name="gripper_assembly">
<visual>
<origin xyz="-0.00075000026822089754797 -0.014749999999999985345 -0.019999999791406958272" rpy="-1.570796326794896558 -2.1930331350620483358e-16 -2.072827123431163489e-30" />
<geometry>
<mesh filename="package:///static_side.stl"/>
</geometry>
<material name="static_side_material">
<color rgba="0.91764705882352937127 0.91764705882352937127 0.91764705882352937127 1.0"/>
</material>
</visual>
<collision>
<origin xyz="-0.00075000026822089754797 -0.014749999999999985345 -0.019999999791406958272" rpy="-1.570796326794896558 -2.1930331350620483358e-16 -2.072827123431163489e-30" />
<geometry>
<mesh filename="package:///static_side.stl"/>
</geometry>
</collision>
<visual>
<origin xyz="0.0075500000000000705436 0.0113499999999986112 -0.012999999999999595213" rpy="-1.5707963267948972241 1.5707963267948898967 0" />
<geometry>
<mesh filename="package:///dc15_a01_horn_idle2_dummy.stl"/>
</geometry>
<material name="dc15_a01_horn_idle2_dummy_material">
<color rgba="0.64705882352941179736 0.64705882352941179736 0.64705882352941179736 1.0"/>
</material>
</visual>
<collision>
<origin xyz="0.0075500000000000705436 0.0113499999999986112 -0.012999999999999595213" rpy="-1.5707963267948972241 1.5707963267948898967 0" />
<geometry>
<mesh filename="package:///dc15_a01_horn_idle2_dummy.stl"/>
</geometry>
</collision>
<visual>
<origin xyz="0.0075500000000000705436 -0.0082500000000000073275 -0.012999999999999900524" rpy="1.5707963267948961139 1.5707963267948961139 0" />
<geometry>
<mesh filename="package:///dc15_a01_case_m_dummy.stl"/>
</geometry>
<material name="dc15_a01_case_m_dummy_material">
<color rgba="0.61568627450980395466 0.81176470588235294379 0.92941176470588238168 1.0"/>
</material>
</visual>
<collision>
<origin xyz="0.0075500000000000705436 -0.0082500000000000073275 -0.012999999999999900524" rpy="1.5707963267948961139 1.5707963267948961139 0" />
<geometry>
<mesh filename="package:///dc15_a01_case_m_dummy.stl"/>
</geometry>
</collision>
<visual>
<origin xyz="0.0075500000000000705436 -0.0082500000000000073275 -0.012999999999999900524" rpy="1.5707963267948961139 1.5707963267948961139 0" />
<geometry>
<mesh filename="package:///dc15_a01_case_f_dummy.stl"/>
</geometry>
<material name="dc15_a01_case_f_dummy_material">
<color rgba="0.98039215686274505668 0.71372549019607844922 0.0039215686274509803377 1.0"/>
</material>
</visual>
<collision>
<origin xyz="0.0075500000000000705436 -0.0082500000000000073275 -0.012999999999999900524" rpy="1.5707963267948961139 1.5707963267948961139 0" />
<geometry>
<mesh filename="package:///dc15_a01_case_f_dummy.stl"/>
</geometry>
</collision>
<visual>
<origin xyz="0.0075500000000000705436 -0.011849999999999860645 -0.012999999999999761746" rpy="-3.1415926535897926719 -1.5707963267948961139 0" />
<geometry>
<mesh filename="package:///dc15_a01_horn_dummy.stl"/>
</geometry>
<material name="dc15_a01_horn_dummy_material">
<color rgba="0.97254901960784312376 0.52941176470588235947 0.0039215686274509803377 1.0"/>
</material>
</visual>
<collision>
<origin xyz="0.0075500000000000705436 -0.011849999999999860645 -0.012999999999999761746" rpy="-3.1415926535897926719 -1.5707963267948961139 0" />
<geometry>
<mesh filename="package:///dc15_a01_horn_dummy.stl"/>
</geometry>
</collision>
<visual>
<origin xyz="0.0075500000000000289102 0.011249999999999843459 -0.012999999999999567457" rpy="1.5707963267948961139 1.5707963267948961139 0" />
<geometry>
<mesh filename="package:///dc15_a01_case_b_dummy.stl"/>
</geometry>
<material name="dc15_a01_case_b_dummy_material">
<color rgba="0.49803921568627451677 0.49803921568627451677 0.49803921568627451677 1.0"/>
</material>
</visual>
<collision>
<origin xyz="0.0075500000000000289102 0.011249999999999843459 -0.012999999999999567457" rpy="1.5707963267948961139 1.5707963267948961139 0" />
<geometry>
<mesh filename="package:///dc15_a01_case_b_dummy.stl"/>
</geometry>
</collision>
<inertial>
<origin xyz="-0.0054859499104701675218 -0.00043314310322922669038 -0.019079257717705720016" rpy="0 0 0"/>
<mass value="0.036062665681300815068" />
<inertia ixx="1.086043043352264727e-05" ixy="4.9639185644185015371e-08"  ixz="-2.8266261983958880842e-06" iyy="1.3259505920145672875e-05" iyz="2.0611038623226464767e-08" izz="6.8042571985414202537e-06" />
</inertial>
</link>

<link name="moving_side">
<visual>
<origin xyz="-0.0083819851589327712404 -0.00025659138241629353416 -0.002999999999999974909" rpy="-1.0169492270965582648e-29 3.3234861782419698549e-32 5.2599109656461859112e-31" />
<geometry>
<mesh filename="package:///moving_side.stl"/>
</geometry>
<material name="moving_side_material">
<color rgba="0.76862745098039220171 0.88627450980392152857 0.95294117647058818044 1.0"/>
</material>
</visual>
<collision>
<origin xyz="-0.0083819851589327712404 -0.00025659138241629353416 -0.002999999999999974909" rpy="-1.0169492270965582648e-29 3.3234861782419698549e-32 5.2599109656461859112e-31" />
<geometry>
<mesh filename="package:///moving_side.stl"/>
</geometry>
</collision>
<inertial>
<origin xyz="-0.00039559915140899293284 0.022415019205288485432 0.014563572484570880272" rpy="0 0 0"/>
<mass value="0.0089856013580471953694" />
<inertia ixx="3.2599103095409282981e-06" ixy="2.1289550108310205084e-07"  ixz="-2.2821854369281786746e-09" iyy="1.4418452272269956788e-06" iyz="3.9277886381779632675e-08" izz="2.2471293915746305858e-06" />
</inertial>
</link>

<joint name="gripper_opening" type="revolute">
<origin xyz="0.0075500000000000705436 -0.014749999999999818812 -0.012999999999999761746" rpy="-1.570796326794896336 5.2990621888091684792e-16 5.3326179148022874402e-16" />
<parent link="gripper_assembly" />
<child link="moving_side" />
<axis xyz="0 0 1"/>
<limit effort="1" velocity="20" lower="-1.7453292519943295336" upper="0.052359877559829889893"/>
<joint_properties friction="0.0"/>
</joint>

<joint name="effector_roll" type="revolute">
<origin xyz="-7.4415414751116681913e-06 -0.045000198961634069184 0.013396676675037827442" rpy="-1.5707963267949769381 -1.5707963267948839015 0" />
<parent link="effector_roll_assembly" />
<child link="gripper_assembly" />
<axis xyz="0 0 1"/>
<limit effort="1" velocity="20" lower="-2.9670597283903603625" upper="2.9670597283903603625"/>
<joint_properties friction="0.0"/>
</joint>

<joint name="pitch3" type="revolute">
<origin xyz="-0.10047608430634623333 -0.0026998601445659686782 0.029249999999998155947" rpy="-3.141592653589793116 1.6546337163891822792e-16 1.5707963267949698327" />
<parent link="pitch3_assembly" />
<child link="effector_roll_assembly" />
<axis xyz="0 0 1"/>
<limit effort="1" velocity="20" lower="-1.9198621771937625091" upper="1.9198621771937625091"/>
<joint_properties friction="0.0"/>
</joint>

<joint name="pitch2" type="revolute">
<origin xyz="0.10830000000000046534 -0.014799999999999417788 0.0042499999999997470357" rpy="-1.0014409002365852962e-15 -9.6676883443502722874e-16 1.5707963267949280883" />
<parent link="pitch2_assembly" />
<child link="pitch3_assembly" />
<axis xyz="0 0 1"/>
<limit effort="1" velocity="20" lower="-1.4835298641951801812" upper="1.7453292519943295336"/>
<joint_properties friction="0.0"/>
</joint>

<joint name="pitch1" type="revolute">
<origin xyz="-0.018799999999999979922 6.9388939039072283776e-17 0.015399999999999983147" rpy="3.141592653589793116 -1.5707963267948645836 0" />
<parent link="pitch1_assembly" />
<child link="pitch2_assembly" />
<axis xyz="0 0 1"/>
<limit effort="1" velocity="20" lower="-1.570796326794896558" upper="1.2217304763960306069"/>
<joint_properties friction="0.0"/>
</joint>

<joint name="yaw" type="revolute">
<origin xyz="0.040155457064714558668 0.032624643463731207993 0.016657302029726331338" rpy="3.9443045261050660336e-31 3.4423324846455909309e-47 9.0205620750793944258e-17" />
<parent link="simple_base_v9" />
<child link="pitch1_assembly" />
<axis xyz="0 0 1"/>
<limit effort="1" velocity="20" lower="-3.141592653589793116" upper="3.141592653589793116"/>
<joint_properties friction="0.0"/>
</joint>


</robot>
